Workbook

Sheet Brand_Sustainability
A1: Brand | B1: Parent_Company | C1: DFW_Locations | D1: Store_Type | E1: Reports_ESG | F1: CDP_Score | G1: SBTi_Status | H1: Emissions_Target | I1: Renewable_Pct | J1: Renewable_Note | K1: Waste_Diversion_Pct | L1: Waste_Note | M1: Notable_Programs | N1: Report_URL | O1: Confidence | P1: Data_Note | Q1: Sub_Reporting | R1: Sub_Target | S1: Sub_Renewable | T1: Sub_Waste | U1: Sub_Programs | V1: Score_Raw_0to10 | W1: Sustain_Score_1to5 | X1: Sustain_Label
A2: Walmart | B2: Walmart Inc. | C2: 126 | D2: Super Store | E2: Yes | F2: Not public (last confirmed A, 2019) | G2: Near-term validated (2026) | H2: Scope 1+2 -28% by FY2031 vs FY2025; zero-emissions aspiration 2040 | I2: 53.3 | J2: 53.3% global electricity FY2026; 100% by 2035 goal | K2: 84 | L2: 84% operational waste diverted FY2026 | M2: Project Gigaton supplier program; 10 GW clean energy pledge | N2: https://corporate.walmart.com/purpose/esgreport | O2: High | P2: Missed 2025 targets; new SBTi-validated target set 2026 | Q2: 2 | R2: 2 | S2: 2 | T2: 2 | U2: 2 | V2: =SUM(Q2:U2) -> 10 | W2: =MIN(5,INT(V2/2)+1) -> 5 | X2: {=INDEX(Rubric!$B$12:$B$16,MATCH(W2,Rubric!$A$12:$A$16,0))} -> Leader
A3: Sam's Club | B3: Walmart Inc. | C3: 23 | D3: Super Store | E3: Yes (via Walmart) | F3: See Walmart | G3: See Walmart | H3: See Walmart | I3: 53.3 | J3: Inherits Walmart Inc. figure | K3: 84 | L3: Inherits Walmart Inc. figure | M3: Walmart Inc. programs | N3: https://corporate.walmart.com/purpose/esgreport | O3: Medium | P3: No standalone reporting; all metrics inherited from Walmart Inc. | Q3: 2 | R3: 2 | S3: 2 | T3: 2 | U3: 2 | V3: =SUM(Q3:U3) -> 10 | W3: =MIN(5,INT(V3/2)+1) -> 5 | X3: {=INDEX(Rubric!$B$12:$B$16,MATCH(W3,Rubric!$A$12:$A$16,0))} -> Leader
A4: Target | B4: Target Corporation | C4: 49 | D4: Super Store | E4: Yes | F4: Not public | G4: Near-term validated (2019); updated targets pending | H4: Scope 1+2 -55% by 2030 vs 2017 (-41% by 2024); net zero 2040 | I4: 76 | J4: 76% renewable electricity 2024; 100% by 2030 | K4: 87 | L4: 87% landfill diversion 2024; 90% by 2030 | M4: Target Forward; Forward Renew supplier program; Target Zero | N4: https://corporate.target.com/sustainability-governance/climate | O4: High | Q4: 2 | R4: 2 | S4: 2 | T4: 2 | U4: 2 | V4: =SUM(Q4:U4) -> 10 | W4: =MIN(5,INT(V4/2)+1) -> 5 | X4: {=INDEX(Rubric!$B$12:$B$16,MATCH(W4,Rubric!$A$12:$A$16,0))} -> Leader
A5: Costco | B5: Costco Wholesale Corp. | C5: 16 | D5: Super Store | E5: Yes | F5: Not public | G5: None (states it has not adopted SBTs) | H5: Scope 1+2 -39% by 2030 vs 2020 (-2% so far); no net-zero year | I5: 28 | J5: 28% clean electricity 2024; 100% by 2035 | K5: 82.8 | L5: 82.8% diverted FY2025 | M5: Climate Action Plan; supplier emissions engagement | N5: https://www.costco.com/sustainability-climate-action-plan.html | O5: High | P5: Little progress on target to date | Q5: 2 | R5: 1 | S5: 1 | T5: 2 | U5: 1 | V5: =SUM(Q5:U5) -> 7 | W5: =MIN(5,INT(V5/2)+1) -> 4 | X5: {=INDEX(Rubric!$B$12:$B$16,MATCH(W5,Rubric!$A$12:$A$16,0))} -> Strong
A6: BJ's Wholesale Club | B6: BJ's Wholesale Club Holdings | C6: 2 | D6: Super Store | E6: Partial (2022 report) | F6: Not public | G6: None (2022 pledge unfulfilled) | H6: None; Scope 1+2 baseline only | J6: ~6% on-site solar FY2023; no target | L6: No % reported; 50% food-waste-reduction pledge by 2030 | M6: Feeding Communities donations; rooftop solar | N6: https://www.bjs.com/biz/BJsESGContentEspot/BJs_ESGReport_2022.pdf | O6: Low | P6: Layer lists as 'BJ's Wholesale Club 252/264'; ESG content removed from site | Q6: 1 | R6: 0 | S6: 0 | T6: 1 | U6: 1 | V6: =SUM(Q6:U6) -> 3 | W6: =MIN(5,INT(V6/2)+1) -> 2 | X6: {=INDEX(Rubric!$B$12:$B$16,MATCH(W6,Rubric!$A$12:$A$16,0))} -> Limited
A7: Kroger | B7: The Kroger Co. | C7: 87 | D7: Supermarket | E7: Yes | F7: Not public | G7: Committed (2022), not validated | H7: Scope 1+2 -30% by 2030 vs 2018 (-15% by 2024); no net-zero year | J7: Not reported | K7: 85 | L7: 85% operational diversion 2024 | M7: Zero Hunger | Zero Waste; natural refrigerants | N7: https://www.thekrogerco.com/impact/reporting-hub/ | O7: Medium-High | P7: Renewable % not disclosed | Q7: 2 | R7: 1 | S7: 0 | T7: 2 | U7: 2 | V7: =SUM(Q7:U7) -> 7 | W7: =MIN(5,INT(V7/2)+1) -> 4 | X7: {=INDEX(Rubric!$B$12:$B$16,MATCH(W7,Rubric!$A$12:$A$16,0))} -> Strong
A8: Albertsons | B8: Albertsons Companies | C8: 27 | D8: Supermarket | E8: Yes | F8: Not public | G8: Near-term validated (~2022) | H8: Scope 1+2 -47% by 2030 vs 2019 (-24% by FY2024); net zero ops 2040 | I8: 48 | J8: 48% green power (EPA GPP Oct 2024) | L8: Zero food waste to landfill by 2030; 325M lbs diverted FY2024; no % reported | M8: Recipe for Change; Nourishing Neighbors | N8: https://s29.q4cdn.com/239956855/files/doc_downloads/2025/12/RecipeForChangeReport2025.pdf | O8: High | Q8: 2 | R8: 2 | S8: 1 | T8: 1 | U8: 2 | V8: =SUM(Q8:U8) -> 8 | W8: =MIN(5,INT(V8/2)+1) -> 5 | X8: {=INDEX(Rubric!$B$12:$B$16,MATCH(W8,Rubric!$A$12:$A$16,0))} -> Leader
A9: Tom Thumb | B9: Albertsons Companies | C9: 68 | D9: Supermarket | E9: Yes (via Albertsons) | F9: See Albertsons | G9: See Albertsons | H9: See Albertsons | I9: 48 | J9: Inherits Albertsons figure | L9: Inherits Albertsons | M9: Albertsons programs | N9: https://s29.q4cdn.com/239956855/files/doc_downloads/2025/12/RecipeForChangeReport2025.pdf | O9: High | P9: Banner; metrics are Albertsons consolidated | Q9: 2 | R9: 2 | S9: 1 | T9: 1 | U9: 2 | V9: =SUM(Q9:U9) -> 8 | W9: =MIN(5,INT(V9/2)+1) -> 5 | X9: {=INDEX(Rubric!$B$12:$B$16,MATCH(W9,Rubric!$A$12:$A$16,0))} -> Leader
A10: Market Street | B10: United Supermarkets / Albertsons | C10: 10 | D10: Supermarket | E10: Yes (via Albertsons) | F10: See Albertsons | G10: See Albertsons | H10: See Albertsons | I10: 48 | J10: Inherits Albertsons figure | L10: Inherits Albertsons | M10: Albertsons programs | N10: https://s29.q4cdn.com/239956855/files/doc_downloads/2025/12/RecipeForChangeReport2025.pdf | O10: High | P10: Banner; metrics are Albertsons consolidated | Q10: 2 | R10: 2 | S10: 1 | T10: 1 | U10: 2 | V10: =SUM(Q10:U10) -> 8 | W10: =MIN(5,INT(V10/2)+1) -> 5 | X10: {=INDEX(Rubric!$B$12:$B$16,MATCH(W10,Rubric!$A$12:$A$16,0))} -> Leader
A11: ALDI | B11: ALDI Inc. (ALDI SUD Group) | C11: 57 | D11: Supermarket | E11: Yes | F11: Not public | G11: Net-zero validated (2024) | H11: Scope 1+2 -52% by 2030, -90% by 2035 vs 2021; net zero 2050 | I11: 100 | J11: 100% renewable (RECs) 6 yrs running; EPA GPP #4 retail | K11: 82.4 | L11: 82.4% diverted 2024; 90% goal | M11: Natural refrigerants (33% of stores); no plastic bags; on-site solar | N11: https://corporate.aldi.us/corporate-sustainability/progress-report | O11: High | Q11: 2 | R11: 2 | S11: 2 | T11: 2 | U11: 2 | V11: =SUM(Q11:U11) -> 10 | W11: =MIN(5,INT(V11/2)+1) -> 5 | X11: {=INDEX(Rubric!$B$12:$B$16,MATCH(W11,Rubric!$A$12:$A$16,0))} -> Leader
A12: H-E-B | B12: H-E-B, LP (private) | C12: 13 | D12: Supermarket | E12: Partial (web only) | F12: None | G12: None | H12: None disclosed | J12: 67 rooftop solar sites; 5 MW wind; no % | K12: 60 | L12: 60% diversion (2020); 87M lbs composted 2025 | M12: Our Texas, Our Future; EPA GreenChill/SmartWay | N12: https://ourtexasourfuture.com/ | O12: Medium | P12: No GHG inventory or targets | Q12: 1 | R12: 0 | S12: 0 | T12: 1 | U12: 1 | V12: =SUM(Q12:U12) -> 3 | W12: =MIN(5,INT(V12/2)+1) -> 2 | X12: {=INDEX(Rubric!$B$12:$B$16,MATCH(W12,Rubric!$A$12:$A$16,0))} -> Limited
A13: Central Market | B13: H-E-B, LP | C13: 7 | D13: Supermarket | E13: Partial (via H-E-B) | F13: None | G13: None | H13: None disclosed | J13: Inherits H-E-B | K13: 60 | L13: Inherits H-E-B (2020) | M13: H-E-B programs | N13: https://ourtexasourfuture.com/ | O13: Medium | P13: Banner; metrics are H-E-B parent | Q13: 1 | R13: 0 | S13: 0 | T13: 1 | U13: 1 | V13: =SUM(Q13:U13) -> 3 | W13: =MIN(5,INT(V13/2)+1) -> 2 | X13: {=INDEX(Rubric!$B$12:$B$16,MATCH(W13,Rubric!$A$12:$A$16,0))} -> Limited
A14: Whole Foods Market | B14: Amazon.com, Inc. | C14: 15 | D14: Super Store | E14: Partial (impact report, no GHG) | F14: Not public | G14: None (Amazon commitment removed 2023) | H14: No WFM target; Amazon net zero 2040 (Climate Pledge) | J14: Not reported; 61 stores with solar; Amazon 100% matched | K14: 70 | L14: 70% diverted (2023); 96% of stores in diversion programs | M14: Natural refrigerants in new stores; food rescue; US Food Waste Pact | N14: https://impact.wholefoods.com/ | O14: Medium | P14: Climate metrics rely on Amazon parent | Q14: 1 | R14: 1 | S14: 1 | T14: 1 | U14: 2 | V14: =SUM(Q14:U14) -> 6 | W14: =MIN(5,INT(V14/2)+1) -> 4 | X14: {=INDEX(Rubric!$B$12:$B$16,MATCH(W14,Rubric!$A$12:$A$16,0))} -> Strong
A15: Sprouts Farmers Market | B15: Sprouts Farmers Market, Inc. | C15: 31 | D15: Supermarket | E15: Yes | F15: None | G15: None | H15: None; discloses Scope 1+2 (-2.8% y/y 2025) | J15: Not reported | K15: 73 | L15: 73% diversion 2025 | M15: Food Rescue (30M meals); low-GWP refrigeration | N15: https://investors.sprouts.com/impact-reports/default.aspx | O15: High | P15: Reports data but sets no targets | Q15: 2 | R15: 0 | S15: 0 | T15: 1 | U15: 1 | V15: =SUM(Q15:U15) -> 4 | W15: =MIN(5,INT(V15/2)+1) -> 3 | X15: {=INDEX(Rubric!$B$12:$B$16,MATCH(W15,Rubric!$A$12:$A$16,0))} -> Moderate
A16: Trader Joe's | B16: Trader Joe's Co. (private, Aldi Nord family) | C16: 11 | D16: Supermarket | E16: No | F16: None | G16: None | H16: None disclosed | J16: Not reported | L16: Not reported | M16: Neighborhood Shares food donation | N16: None | O16: Low | P16: No sustainability report; EIA scorecard 17% | Q16: 0 | R16: 0 | S16: 0 | T16: 0 | U16: 1 | V16: =SUM(Q16:U16) -> 1 | W16: =MIN(5,INT(V16/2)+1) -> 1 | X16: {=INDEX(Rubric!$B$12:$B$16,MATCH(W16,Rubric!$A$12:$A$16,0))} -> None / Undisclosed
A17: WinCo Foods | B17: WinCo Foods, LLC (ESOP) | C17: 10 | D17: Supermarket | E17: No | F17: None | G17: None | H17: None disclosed | J17: Not reported | L17: Not reported | M17: Food bank donations only | N17: None | O17: Low | P17: No disclosures | Q17: 0 | R17: 0 | S17: 0 | T17: 0 | U17: 0 | V17: =SUM(Q17:U17) -> 0 | W17: =MIN(5,INT(V17/2)+1) -> 1 | X17: {=INDEX(Rubric!$B$12:$B$16,MATCH(W17,Rubric!$A$12:$A$16,0))} -> None / Undisclosed
A18: Fiesta Mart | B18: Chedraui USA / Grupo Chedraui | C18: 29 | D18: Supermarket | E18: Partial (parent, Mexico-focused) | F18: Not public | G18: None | H18: None; parent discloses Scope 1+2 | J18: Parent 63% renewable (Mexico ops only); US not reported | L18: Not reported | M18: Parent IFRS S2 climate report; sustainable seafood | N18: https://inversionistas.grupochedraui.com.mx/ | O18: Medium | P18: No Fiesta-specific data | Q18: 1 | R18: 0 | S18: 0 | T18: 0 | U18: 1 | V18: =SUM(Q18:U18) -> 2 | W18: =MIN(5,INT(V18/2)+1) -> 2 | X18: {=INDEX(Rubric!$B$12:$B$16,MATCH(W18,Rubric!$A$12:$A$16,0))} -> Limited
A19: El Rancho Supermercado | B19: Heritage Grocers Group (Apollo) | C19: 20 | D19: Supermarket | E19: Partial (press only) | F19: None | G19: None | H19: None; group cut Scope 1+2 13% y/y (2024) | J19: Renewable PPA for TX stores announced 2024; no % | L19: 1.5M lbs food diverted (group); no % | M19: Renewable PPA; LED/HVAC; refrigerant leak tagging | N19: None | O19: Medium | P19: Owned by Heritage Grocers since 2023, not Chedraui | Q19: 1 | R19: 0 | S19: 0 | T19: 1 | U19: 1 | V19: =SUM(Q19:U19) -> 3 | W19: =MIN(5,INT(V19/2)+1) -> 2 | X19: {=INDEX(Rubric!$B$12:$B$16,MATCH(W19,Rubric!$A$12:$A$16,0))} -> Limited
A20: El Rio Grande Latin Market | B20: Private (Dallas) | C20: 9 | D20: Supermarket | E20: No | F20: None | G20: None | H20: None | J20: Not reported | L20: Not reported | M20: None found | N20: None | O20: High (none published) | Q20: 0 | R20: 0 | S20: 0 | T20: 0 | U20: 0 | V20: =SUM(Q20:U20) -> 0 | W20: =MIN(5,INT(V20/2)+1) -> 1 | X20: {=INDEX(Rubric!$B$12:$B$16,MATCH(W20,Rubric!$A$12:$A$16,0))} -> None / Undisclosed
A21: La Michoacana | B21: La Michoacana Meat Market (private, Houston) | C21: 37 | D21: Grocery Store | E21: No | F21: None | G21: None | H21: None | J21: Not reported | L21: Not reported | M21: None found | N21: None | O21: High (none published) | Q21: 0 | R21: 0 | S21: 0 | T21: 0 | U21: 0 | V21: =SUM(Q21:U21) -> 0 | W21: =MIN(5,INT(V21/2)+1) -> 1 | X21: {=INDEX(Rubric!$B$12:$B$16,MATCH(W21,Rubric!$A$12:$A$16,0))} -> None / Undisclosed
A22: Natural Grocers | B22: Natural Grocers by Vitamin Cottage (NYSE: NGVC) | C22: 6 | D22: Supermarket | E22: Partial (qualitative report) | F22: None | G22: None | H22: None disclosed | J22: Not reported | L22: No % reported; 500M plastic bags avoided since 2009 | M22: First US grocer to ban plastic checkout bags (2009); PG Most Sustainable Grocers 2025/26 | N22: https://www.naturalgrocers.com/sustainability-report | O22: High | P22: Report lacks GHG metrics | Q22: 1 | R22: 0 | S22: 0 | T22: 0 | U22: 2 | V22: =SUM(Q22:U22) -> 3 | W22: =MIN(5,INT(V22/2)+1) -> 2 | X22: {=INDEX(Rubric!$B$12:$B$16,MATCH(W22,Rubric!$A$12:$A$16,0))} -> Limited
A23: Brookshire's | B23: Brookshire Grocery Co. (private, Tyler TX) | C23: 4 | D23: Supermarket | E23: No | F23: None | G23: None | H23: None | J23: Not reported | L23: Not reported; ~600K lbs food donated/yr | M23: EPA SmartWay; bag/bottle recycling; food bank giving | N23: None | O23: Medium | Q23: 0 | R23: 0 | S23: 0 | T23: 0 | U23: 1 | V23: =SUM(Q23:U23) -> 1 | W23: =MIN(5,INT(V23/2)+1) -> 1 | X23: {=INDEX(Rubric!$B$12:$B$16,MATCH(W23,Rubric!$A$12:$A$16,0))} -> None / Undisclosed
A24: H Mart | B24: H Mart Inc. (private) | C24: 3 | D24: Supermarket | E24: No | F24: None | G24: None | H24: None | J24: Not reported | L24: Not reported | M24: None found | N24: None | O24: High (none published) | Q24: 0 | R24: 0 | S24: 0 | T24: 0 | U24: 0 | V24: =SUM(Q24:U24) -> 0 | W24: =MIN(5,INT(V24/2)+1) -> 1 | X24: {=INDEX(Rubric!$B$12:$B$16,MATCH(W24,Rubric!$A$12:$A$16,0))} -> None / Undisclosed
A25: 99 Ranch Market | B25: Tawa Supermarket, Inc. (private) | C25: 3 | D25: Supermarket | E25: No | F25: None | G25: None | H25: None | J25: Not reported | L25: Single-store EPA Food Recovery award (2018) | M25: EPA Food Recovery Challenge award (2018) | N25: None | O25: Medium | P25: Dated, single-store datapoint | Q25: 0 | R25: 0 | S25: 0 | T25: 0 | U25: 1 | V25: =SUM(Q25:U25) -> 1 | W25: =MIN(5,INT(V25/2)+1) -> 1 | X25: {=INDEX(Rubric!$B$12:$B$16,MATCH(W25,Rubric!$A$12:$A$16,0))} -> None / Undisclosed
A26: Patel Brothers | B26: Patel Brothers (private) | C26: 4 | D26: Grocery Store | E26: No | F26: None | G26: None | H26: None | J26: Not reported | L26: Not reported | M26: None found | N26: None | O26: High (none published) | Q26: 0 | R26: 0 | S26: 0 | T26: 0 | U26: 0 | V26: =SUM(Q26:U26) -> 0 | W26: =MIN(5,INT(V26/2)+1) -> 1 | X26: {=INDEX(Rubric!$B$12:$B$16,MATCH(W26,Rubric!$A$12:$A$16,0))} -> None / Undisclosed
A27: Foodland | B27: G.E. Foodland, Inc. (private, DFW) | C27: 9 | D27: Supermarket | E27: No | F27: None | G27: None | H27: None | J27: Not reported | L27: Not reported | M27: Local food bank support | N27: None | O27: High (none published) | P27: Assumed G.E. Foodland | Q27: 0 | R27: 0 | S27: 0 | T27: 0 | U27: 0 | V27: =SUM(Q27:U27) -> 0 | W27: =MIN(5,INT(V27/2)+1) -> 1 | X27: {=INDEX(Rubric!$B$12:$B$16,MATCH(W27,Rubric!$A$12:$A$16,0))} -> None / Undisclosed
A28: India Bazaar | B28: Private (Pabari family, Plano) | C28: 9 | D28: Grocery Store | E28: No | F28: None | G28: None | H28: None | J28: Not reported | L28: Not reported | M28: None found | N28: None | O28: High (none published) | Q28: 0 | R28: 0 | S28: 0 | T28: 0 | U28: 0 | V28: =SUM(Q28:U28) -> 0 | W28: =MIN(5,INT(V28/2)+1) -> 1 | X28: {=INDEX(Rubric!$B$12:$B$16,MATCH(W28,Rubric!$A$12:$A$16,0))} -> None / Undisclosed
A29: 7-Eleven | B29: Seven & i Holdings / 7-Eleven, Inc. | C29: 424 | D29: Convenience Store | E29: Yes | F29: Not public | G29: None found | H29: Store Scope 1+2 -50% by 2030 vs FY2013 (-33% by FY2024); net zero 2050 | I29: 23 | J29: ~23% of US/Canada store electricity FY2024 | L29: 50% food-waste reduction goal by 2030; no % | M29: 7Charge EV network; HVAC efficiency program | N29: https://corp.7-eleven.com/corp-press-releases/7-eleven-inc-releases-2025-impact-report | O29: Medium | Q29: 2 | R29: 1 | S29: 1 | T29: 1 | U29: 1 | V29: =SUM(Q29:U29) -> 6 | W29: =MIN(5,INT(V29/2)+1) -> 4 | X29: {=INDEX(Rubric!$B$12:$B$16,MATCH(W29,Rubric!$A$12:$A$16,0))} -> Strong
A30: Dollar General | B30: Dollar General Corp. (NYSE: DG) | C30: 184 | D30: Other | E30: Yes | F30: Not public | G30: None | H30: Intensity only: -15% by 2026 (met), -30% by 2031 vs 2020 per sq ft | J30: Not reported as %; ~3,300 stores on wind/solar agreements | K30: 66 | L30: 66% landfill diversion 2025 | M30: ISO 50001 energy mgmt in 99% of stores | N30: https://www.dollargeneral.com/content/dam/dg/assets/landing-pages/public-relations/corporate-social-responsibility/documents/Serving-Others-Report-FY25.pdf | O30: High | P30: No absolute target | Q30: 2 | R30: 1 | S30: 0 | T30: 1 | U30: 1 | V30: =SUM(Q30:U30) -> 5 | W30: =MIN(5,INT(V30/2)+1) -> 3 | X30: {=INDEX(Rubric!$B$12:$B$16,MATCH(W30,Rubric!$A$12:$A$16,0))} -> Moderate
A31: Dollar Tree | B31: Dollar Tree, Inc. (NASDAQ: DLTR) | C31: 151 | D31: Other | E31: Yes | F31: Not public (publishes CDP response) | G31: None (1.5C-aligned, unvalidated) | H31: Scope 1+2 -50% by FY2032 vs FY2023; net zero 2050 | J31: Not reported as %; solar PPAs from 2026 | K31: 70 | L31: 70% diversion FY2025 | M31: Energy Efficiency Standard for new stores | N31: https://corporate.dollartree.com/values/environmental-stewardship | O31: High | Q31: 2 | R31: 1 | S31: 0 | T31: 1 | U31: 1 | V31: =SUM(Q31:U31) -> 5 | W31: =MIN(5,INT(V31/2)+1) -> 3 | X31: {=INDEX(Rubric!$B$12:$B$16,MATCH(W31,Rubric!$A$12:$A$16,0))} -> Moderate
A32: Family Dollar | B32: Brigade Capital / Macellum (private since Jul 2025) | C32: 179 | D32: Other | E32: No | F32: None | G32: None | H32: None since divestiture from Dollar Tree | J32: Not reported | L32: Not reported | M32: None post-divestiture | N32: None | O32: Low | P32: Excluded from Dollar Tree reporting after 2025 sale | Q32: 0 | R32: 0 | S32: 0 | T32: 0 | U32: 0 | V32: =SUM(Q32:U32) -> 0 | W32: =MIN(5,INT(V32/2)+1) -> 1 | X32: {=INDEX(Rubric!$B$12:$B$16,MATCH(W32,Rubric!$A$12:$A$16,0))} -> None / Undisclosed
A33: CVS | B33: CVS Health Corp. (NYSE: CVS) | C33: 174 | D33: Other | E33: Yes | F33: A- (secondary source, undated) | G33: Net-zero validated (2021) | H33: Scope 1+2 -47% by 2030 vs 2019 (-43% by 2025); net zero 2050 | I33: 33 | J33: 33% renewable energy 2025; 50% by 2040 | K33: 63 | L33: 63% diversion 2025 | M33: Seven renewable PPAs; fleet electrification | N33: https://www.cvshealth.com/impact/healthy-planet/climate-resiliency-and-energy.html | O33: High | Q33: 2 | R33: 2 | S33: 1 | T33: 1 | U33: 2 | V33: =SUM(Q33:U33) -> 8 | W33: =MIN(5,INT(V33/2)+1) -> 5 | X33: {=INDEX(Rubric!$B$12:$B$16,MATCH(W33,Rubric!$A$12:$A$16,0))} -> Leader
A34: Walgreens | B34: Walgreens Boots Alliance (private, Sycamore 2025) | C34: 153 | D34: Other | E34: Yes | F34: B (FY2018, dated) | G34: None | H34: Scope 1+2 -30% by FY2030 vs FY2019 (achieved -38% by FY2025); no net zero | I34: 1 | J34: 1% renewable FY2025 | L34: >99% diversion at DCs; landfill waste -45% vs FY2019; no overall % | M34: $500M+ efficiency upgrades; Green Box product recovery | N34: https://corporate.walgreens.com/wp-content/uploads/2026/03/Walgreens-Impact-Report_FY25.pdf | O34: High | Q34: 2 | R34: 1 | S34: 0 | T34: 1 | U34: 1 | V34: =SUM(Q34:U34) -> 5 | W34: =MIN(5,INT(V34/2)+1) -> 3 | X34: {=INDEX(Rubric!$B$12:$B$16,MATCH(W34,Rubric!$A$12:$A$16,0))} -> Moderate
A35: QuikTrip | B35: QuikTrip Corp. (private) | C35: 164 | D35: Convenience Store | E35: No | F35: None | G35: None | H35: None | J35: Not reported | L35: Not reported | M35: None found | N35: None | O35: High (none published) | Q35: 0 | R35: 0 | S35: 0 | T35: 0 | U35: 0 | V35: =SUM(Q35:U35) -> 0 | W35: =MIN(5,INT(V35/2)+1) -> 1 | X35: {=INDEX(Rubric!$B$12:$B$16,MATCH(W35,Rubric!$A$12:$A$16,0))} -> None / Undisclosed
A36: RaceTrac | B36: RaceTrac, Inc. (private) | C36: 99 | D36: Convenience Store | E36: No | F36: None | G36: None | H36: None | J36: Not reported | L36: Not reported | M36: EV chargers (DFW, 2023) | N36: None | O36: High (none published) | P36: Also operates Raceway (10 DFW sites) | Q36: 0 | R36: 0 | S36: 0 | T36: 0 | U36: 1 | V36: =SUM(Q36:U36) -> 1 | W36: =MIN(5,INT(V36/2)+1) -> 1 | X36: {=INDEX(Rubric!$B$12:$B$16,MATCH(W36,Rubric!$A$12:$A$16,0))} -> None / Undisclosed
A37: Raceway | B37: RaceTrac, Inc. (private) | C37: 10 | D37: Convenience Store | E37: No | F37: None | G37: None | H37: None | J37: Not reported | L37: Not reported | M37: See RaceTrac | N37: None | O37: High (none published) | P37: RaceTrac banner | Q37: 0 | R37: 0 | S37: 0 | T37: 0 | U37: 1 | V37: =SUM(Q37:U37) -> 1 | W37: =MIN(5,INT(V37/2)+1) -> 1 | X37: {=INDEX(Rubric!$B$12:$B$16,MATCH(W37,Rubric!$A$12:$A$16,0))} -> None / Undisclosed
A38: Circle K | B38: Alimentation Couche-Tard (TSX: ATD) | C38: 35 | D38: Convenience Store | E38: Yes | F38: Not public | G38: None found | H38: Scope 1+2 -24% vs 2020 achieved FY2026; 30% of sites carbon-neutral by 2030; no net zero | J38: Not reported group-wide; pursuing 100% via VPPAs | L38: Too Good To Go 4M+ meals; packaging goals; no % | M38: 4,700+ EV charge points; $1B renewable investment goal | N38: https://corporate.couche-tard.com/planet/ | O38: Medium | Q38: 2 | R38: 1 | S38: 0 | T38: 1 | U38: 2 | V38: =SUM(Q38:U38) -> 6 | W38: =MIN(5,INT(V38/2)+1) -> 4 | X38: {=INDEX(Rubric!$B$12:$B$16,MATCH(W38,Rubric!$A$12:$A$16,0))} -> Strong
A39: Murphy USA | B39: Murphy USA Inc. (NYSE: MUSA) | C39: 46 | D39: Convenience Store | E39: Partial (SASB summary) | F39: None | G39: None | H39: None; discloses Scope 1+2 only | J39: Not reported | L39: Not reported | M39: Annual ESG Summary only | N39: https://ir.corporate.murphyusa.com/investor-relations/esg-summary/default.aspx | O39: Medium | Q39: 1 | R39: 0 | S39: 0 | T39: 0 | U39: 0 | V39: =SUM(Q39:U39) -> 1 | W39: =MIN(5,INT(V39/2)+1) -> 1 | X39: {=INDEX(Rubric!$B$12:$B$16,MATCH(W39,Rubric!$A$12:$A$16,0))} -> None / Undisclosed
A40: Murphy Express | B40: Murphy USA Inc. | C40: 37 | D40: Convenience Store | E40: Partial (via Murphy USA) | F40: None | G40: None | H40: See Murphy USA | J40: Not reported | L40: Not reported | M40: See Murphy USA | N40: https://ir.corporate.murphyusa.com/investor-relations/esg-summary/default.aspx | O40: Medium | P40: Murphy USA banner | Q40: 1 | R40: 0 | S40: 0 | T40: 0 | U40: 0 | V40: =SUM(Q40:U40) -> 1 | W40: =MIN(5,INT(V40/2)+1) -> 1 | X40: {=INDEX(Rubric!$B$12:$B$16,MATCH(W40,Rubric!$A$12:$A$16,0))} -> None / Undisclosed
...

Sheet Rubric
A1: Dimension | B1: 0 points | C1: 1 point | D1: 2 points
A2: Sub_Reporting | B2: No public sustainability disclosure | C2: Partial: web page, qualitative report, or parent-only | D2: Full annual report with GHG inventory
A3: Sub_Target | B3: No emissions target | C3: Target exists but intensity-based, unvalidated, or parent-level pledge only | D3: Absolute Scope 1+2 target validated by SBTi (near-term or net-zero)
A4: Sub_Renewable | B4: Not reported or <10% renewable electricity | C4: 10-49% renewable electricity | D4: 50%+ renewable electricity
A5: Sub_Waste | B5: Not reported | C5: <80% diversion, or target/volume only without a % | D5: 80%+ landfill diversion
A6: Sub_Programs | B6: None found | C6: Some named programs (donations, efficiency, EV) | D6: Flagship program with measurable scope (e.g. Project Gigaton, Zero Hunger Zero Waste)
A8: Score_Raw_0to10 = sum of the five subscores. Sustain_Score_1to5 = MIN(5, INT(raw/2)+1).
A10: Score mapping
A11: Score | B11: Label | C11: Raw range
A12: 1 | B12: None / Undisclosed | C12: 0-1
A13: 2 | B13: Limited | C13: 2-3
A14: 3 | B14: Moderate | C14: 4-5
A15: 4 | B15: Strong | C15: 6-7
A16: 5 | B16: Leader | C16: 8-10

Sheet Sources
A1: Brand | B1: Source URL
A2: Walmart | B2: https://corporate.walmart.com/purpose/esgreport/climate-resilience-energy-and-emissions
A3: Walmart | B3: https://www.esgtoday.com/walmart-sets-new-sbti-approved-emissions-reduction-target/
A4: Walmart | B4: https://corporate.walmart.com/content/corporate/en_us/purpose/esgreport/environmental/waste-circular-economy.html
A5: Sam's Club | B5: https://corporate.walmart.com/purpose/esgreport
A6: Target | B6: https://corporate.target.com/sustainability-governance/climate
A7: Target | B7: https://corporate.target.com/getmedia/391e0902-54da-4a88-9325-4fa0098c2665/2025-Sustainability-and-Governance-Report.pdf
A8: Costco | B8: https://s201.q4cdn.com/287523651/files/doc_financials/2025/ar/costco-sustainability-report-2025.pdf
A9: Costco | B9: https://www.costco.com/sustainability-climate-action-plan.html
A10: BJ's Wholesale Club | B10: https://www.bjs.com/biz/BJsESGContentEspot/BJs_ESGReport_2022.pdf
A11: BJ's Wholesale Club | B11: https://www.iccr.org/wp-content/uploads/2026/05/BJs-2026-GHG-Reductions_Exempt-Solicitation_TRILLIUM.pdf
A12: Kroger | B12: https://www.thekrogerco.com/wp-content/uploads/2025/10/Kroger-Co-2025-Responsible-Business-Report.pdf
... A56: Braum's | B56: https://www.braums.com/about/
